Not Found: /accounts/login/
"GET /accounts/login/?next=/profile/ HTTP/1.1" 404 5719
Not Found: /favicon.ico
"GET /favicon.ico HTTP/1.1" 404 5692
Not Found: /favicon.ico
"GET /favicon.ico HTTP/1.1" 404 5679
Not Found: /favicon.ico
"GET /favicon.ico HTTP/1.1" 404 5679
"GET /static/mechanics/css/reject_invoice.css HTTP/1.1" 404 1910
Not Found: /favicon.ico
"GET /favicon.ico HTTP/1.1" 404 5679
Not Found: /favicon.ico
"GET /favicon.ico HTTP/1.1" 404 5679
Not Found: /favicon.ico
"GET /favicon.ico HTTP/1.1" 404 5679
Not Found: /favicon.ico
"GET /favicon.ico HTTP/1.1" 404 5679
Not Found: /favicon.ico
"GET /favicon.ico HTTP/1.1" 404 5679
Not Found: /favicon.ico
"GET /favicon.ico HTTP/1.1" 404 5679
Internal Server Error: /managers/support/
Traceback (most recent call last):
  File "C:\Users\ADMIN\Muranga_transport\venv\Lib\site-packages\django\core\handlers\exception.py", line 55, in inner
    response = get_response(request)
               ^^^^^^^^^^^^^^^^^^^^^
  File "C:\Users\ADMIN\Muranga_transport\venv\Lib\site-packages\django\core\handlers\base.py", line 197, in _get_response
    response = wrapped_callback(request, *callback_args, **callback_kwargs)
               ^^^^^^^^^^^^^^^^^^^^^^^^^^^^^^^^^^^^^^^^^^^^^^^^^^^^^^^^^^^^
  File "C:\Users\ADMIN\Muranga_transport\venv\Lib\site-packages\django\contrib\auth\decorators.py", line 59, in _view_wrapper
    return view_func(request, *args, **kwargs)
           ^^^^^^^^^^^^^^^^^^^^^^^^^^^^^^^^^^^
  File "C:\Users\ADMIN\Muranga_transport\managers\views.py", line 955, in support
    return render(request, 'managers/support.html')
           ^^^^^^^^^^^^^^^^^^^^^^^^^^^^^^^^^^^^^^^^
  File "C:\Users\ADMIN\Muranga_transport\venv\Lib\site-packages\django\shortcuts.py", line 25, in render
    content = loader.render_to_string(template_name, context, request, using=using)
              ^^^^^^^^^^^^^^^^^^^^^^^^^^^^^^^^^^^^^^^^^^^^^^^^^^^^^^^^^^^^^^^^^^^^^
  File "C:\Users\ADMIN\Muranga_transport\venv\Lib\site-packages\django\template\loader.py", line 61, in render_to_string
    template = get_template(template_name, using=using)
               ^^^^^^^^^^^^^^^^^^^^^^^^^^^^^^^^^^^^^^^^
  File "C:\Users\ADMIN\Muranga_transport\venv\Lib\site-packages\django\template\loader.py", line 19, in get_template
    raise TemplateDoesNotExist(template_name, chain=chain)
django.template.exceptions.TemplateDoesNotExist: managers/support.html
"GET /managers/support/ HTTP/1.1" 500 89589
Unauthorized access to support_requests by mechanic_3d216646 (role: mechanic)
Not Found: /favicon.ico
"GET /favicon.ico HTTP/1.1" 404 5679
Unauthorized access to support_requests by manager1 (role: transport_manager)
Unauthorized access to support_requests by manager1 (role: transport_manager)
Not Found: /favicon.ico
"GET /favicon.ico HTTP/1.1" 404 5679
Not Found: /favicon.ico
"GET /favicon.ico HTTP/1.1" 404 5679
Forbidden (CSRF token from POST incorrect.): /login/
"POST /login/ HTTP/1.1" 403 2503
No MechanicProfile for user manager1 (ID: 3, is_staff: False, is_superuser: False)
Internal Server Error: /managers/support/
Traceback (most recent call last):
  File "C:\Users\ADMIN\Muranga_transport\venv\Lib\site-packages\django\db\backends\utils.py", line 105, in _execute
    return self.cursor.execute(sql, params)
           ^^^^^^^^^^^^^^^^^^^^^^^^^^^^^^^^
  File "C:\Users\ADMIN\Muranga_transport\venv\Lib\site-packages\django\db\backends\mysql\base.py", line 76, in execute
    return self.cursor.execute(query, args)
           ^^^^^^^^^^^^^^^^^^^^^^^^^^^^^^^^
  File "C:\Users\ADMIN\Muranga_transport\venv\Lib\site-packages\MySQLdb\cursors.py", line 179, in execute
    res = self._query(mogrified_query)
          ^^^^^^^^^^^^^^^^^^^^^^^^^^^^
  File "C:\Users\ADMIN\Muranga_transport\venv\Lib\site-packages\MySQLdb\cursors.py", line 330, in _query
    db.query(q)
  File "C:\Users\ADMIN\Muranga_transport\venv\Lib\site-packages\MySQLdb\connections.py", line 280, in query
    _mysql.connection.query(self, query)
MySQLdb.ProgrammingError: (1146, "Table 'muranga_transport.managers_supportresponse' doesn't exist")

The above exception was the direct cause of the following exception:

Traceback (most recent call last):
  File "C:\Users\ADMIN\Muranga_transport\venv\Lib\site-packages\django\core\handlers\exception.py", line 55, in inner
    response = get_response(request)
               ^^^^^^^^^^^^^^^^^^^^^
  File "C:\Users\ADMIN\Muranga_transport\venv\Lib\site-packages\django\core\handlers\base.py", line 197, in _get_response
    response = wrapped_callback(request, *callback_args, **callback_kwargs)
               ^^^^^^^^^^^^^^^^^^^^^^^^^^^^^^^^^^^^^^^^^^^^^^^^^^^^^^^^^^^^
  File "C:\Users\ADMIN\Muranga_transport\venv\Lib\site-packages\django\contrib\auth\decorators.py", line 59, in _view_wrapper
    return view_func(request, *args, **kwargs)
           ^^^^^^^^^^^^^^^^^^^^^^^^^^^^^^^^^^^
  File "C:\Users\ADMIN\Muranga_transport\managers\views.py", line 983, in support
    return render(request, 'managers/support_requests.html', {
           ^^^^^^^^^^^^^^^^^^^^^^^^^^^^^^^^^^^^^^^^^^^^^^^^^^^
  File "C:\Users\ADMIN\Muranga_transport\venv\Lib\site-packages\django\shortcuts.py", line 25, in render
    content = loader.render_to_string(template_name, context, request, using=using)
              ^^^^^^^^^^^^^^^^^^^^^^^^^^^^^^^^^^^^^^^^^^^^^^^^^^^^^^^^^^^^^^^^^^^^^
  File "C:\Users\ADMIN\Muranga_transport\venv\Lib\site-packages\django\template\loader.py", line 62, in render_to_string
    return template.render(context, request)
           ^^^^^^^^^^^^^^^^^^^^^^^^^^^^^^^^^
  File "C:\Users\ADMIN\Muranga_transport\venv\Lib\site-packages\django\template\backends\django.py", line 107, in render
    return self.template.render(context)
           ^^^^^^^^^^^^^^^^^^^^^^^^^^^^^
  File "C:\Users\ADMIN\Muranga_transport\venv\Lib\site-packages\django\template\base.py", line 171, in render
    return self._render(context)
           ^^^^^^^^^^^^^^^^^^^^^
  File "C:\Users\ADMIN\Muranga_transport\venv\Lib\site-packages\django\template\base.py", line 163, in _render
    return self.nodelist.render(context)
           ^^^^^^^^^^^^^^^^^^^^^^^^^^^^^
  File "C:\Users\ADMIN\Muranga_transport\venv\Lib\site-packages\django\template\base.py", line 1016, in render
    return SafeString("".join([node.render_annotated(context) for node in self]))
                               ^^^^^^^^^^^^^^^^^^^^^^^^^^^^^^
  File "C:\Users\ADMIN\Muranga_transport\venv\Lib\site-packages\django\template\base.py", line 977, in render_annotated
    return self.render(context)
           ^^^^^^^^^^^^^^^^^^^^
  File "C:\Users\ADMIN\Muranga_transport\venv\Lib\site-packages\django\template\loader_tags.py", line 159, in render
    return compiled_parent._render(context)
           ^^^^^^^^^^^^^^^^^^^^^^^^^^^^^^^^
  File "C:\Users\ADMIN\Muranga_transport\venv\Lib\site-packages\django\template\base.py", line 163, in _render
    return self.nodelist.render(context)
           ^^^^^^^^^^^^^^^^^^^^^^^^^^^^^
  File "C:\Users\ADMIN\Muranga_transport\venv\Lib\site-packages\django\template\base.py", line 1016, in render
    return SafeString("".join([node.render_annotated(context) for node in self]))
                               ^^^^^^^^^^^^^^^^^^^^^^^^^^^^^^
  File "C:\Users\ADMIN\Muranga_transport\venv\Lib\site-packages\django\template\base.py", line 977, in render_annotated
    return self.render(context)
           ^^^^^^^^^^^^^^^^^^^^
  File "C:\Users\ADMIN\Muranga_transport\venv\Lib\site-packages\django\template\loader_tags.py", line 65, in render
    result = block.nodelist.render(context)
             ^^^^^^^^^^^^^^^^^^^^^^^^^^^^^^
  File "C:\Users\ADMIN\Muranga_transport\venv\Lib\site-packages\django\template\base.py", line 1016, in render
    return SafeString("".join([node.render_annotated(context) for node in self]))
                               ^^^^^^^^^^^^^^^^^^^^^^^^^^^^^^
  File "C:\Users\ADMIN\Muranga_transport\venv\Lib\site-packages\django\template\base.py", line 977, in render_annotated
    return self.render(context)
           ^^^^^^^^^^^^^^^^^^^^
  File "C:\Users\ADMIN\Muranga_transport\venv\Lib\site-packages\django\template\defaulttags.py", line 243, in render
    nodelist.append(node.render_annotated(context))
                    ^^^^^^^^^^^^^^^^^^^^^^^^^^^^^^
  File "C:\Users\ADMIN\Muranga_transport\venv\Lib\site-packages\django\template\base.py", line 977, in render_annotated
    return self.render(context)
           ^^^^^^^^^^^^^^^^^^^^
  File "C:\Users\ADMIN\Muranga_transport\venv\Lib\site-packages\django\template\defaulttags.py", line 199, in render
    len_values = len(values)
                 ^^^^^^^^^^^
  File "C:\Users\ADMIN\Muranga_transport\venv\Lib\site-packages\django\db\models\query.py", line 366, in __len__
    self._fetch_all()
  File "C:\Users\ADMIN\Muranga_transport\venv\Lib\site-packages\django\db\models\query.py", line 1949, in _fetch_all
    self._result_cache = list(self._iterable_class(self))
                         ^^^^^^^^^^^^^^^^^^^^^^^^^^^^^^^^
  File "C:\Users\ADMIN\Muranga_transport\venv\Lib\site-packages\django\db\models\query.py", line 91, in __iter__
    results = compiler.execute_sql(
              ^^^^^^^^^^^^^^^^^^^^^
  File "C:\Users\ADMIN\Muranga_transport\venv\Lib\site-packages\django\db\models\sql\compiler.py", line 1623, in execute_sql
    cursor.execute(sql, params)
  File "C:\Users\ADMIN\Muranga_transport\venv\Lib\site-packages\django\db\backends\utils.py", line 122, in execute
    return super().execute(sql, params)
           ^^^^^^^^^^^^^^^^^^^^^^^^^^^^
  File "C:\Users\ADMIN\Muranga_transport\venv\Lib\site-packages\django\db\backends\utils.py", line 79, in execute
    return self._execute_with_wrappers(
           ^^^^^^^^^^^^^^^^^^^^^^^^^^^^
  File "C:\Users\ADMIN\Muranga_transport\venv\Lib\site-packages\django\db\backends\utils.py", line 92, in _execute_with_wrappers
    return executor(sql, params, many, context)
           ^^^^^^^^^^^^^^^^^^^^^^^^^^^^^^^^^^^^
  File "C:\Users\ADMIN\Muranga_transport\venv\Lib\site-packages\django\db\backends\utils.py", line 100, in _execute
    with self.db.wrap_database_errors:
         ^^^^^^^^^^^^^^^^^^^^^^^^^^^^
  File "C:\Users\ADMIN\Muranga_transport\venv\Lib\site-packages\django\db\utils.py", line 91, in __exit__
    raise dj_exc_value.with_traceback(traceback) from exc_value
  File "C:\Users\ADMIN\Muranga_transport\venv\Lib\site-packages\django\db\backends\utils.py", line 105, in _execute
    return self.cursor.execute(sql, params)
           ^^^^^^^^^^^^^^^^^^^^^^^^^^^^^^^^
  File "C:\Users\ADMIN\Muranga_transport\venv\Lib\site-packages\django\db\backends\mysql\base.py", line 76, in execute
    return self.cursor.execute(query, args)
           ^^^^^^^^^^^^^^^^^^^^^^^^^^^^^^^^
  File "C:\Users\ADMIN\Muranga_transport\venv\Lib\site-packages\MySQLdb\cursors.py", line 179, in execute
    res = self._query(mogrified_query)
          ^^^^^^^^^^^^^^^^^^^^^^^^^^^^
  File "C:\Users\ADMIN\Muranga_transport\venv\Lib\site-packages\MySQLdb\cursors.py", line 330, in _query
    db.query(q)
  File "C:\Users\ADMIN\Muranga_transport\venv\Lib\site-packages\MySQLdb\connections.py", line 280, in query
    _mysql.connection.query(self, query)
django.db.utils.ProgrammingError: (1146, "Table 'muranga_transport.managers_supportresponse' doesn't exist")
"GET /managers/support/ HTTP/1.1" 500 263252
Not Found: /favicon.ico
"GET /favicon.ico HTTP/1.1" 404 5679
Not Found: /favicon.ico
"GET /favicon.ico HTTP/1.1" 404 5679
No MechanicProfile for user driver_81addb4d (ID: 12, is_staff: False, is_superuser: False)
Not Found: /favicon.ico
"GET /favicon.ico HTTP/1.1" 404 5679
Not Found: /favicon.ico
"GET /favicon.ico HTTP/1.1" 404 5679
Not Found: /favicon.ico
"GET /favicon.ico HTTP/1.1" 404 5679
Not Found: /favicon.ico
"GET /favicon.ico HTTP/1.1" 404 5679
Not Found: /favicon.ico
"GET /favicon.ico HTTP/1.1" 404 5679
"GET /static/managers/images/murangalogo.png HTTP/1.1" 404 1907
Internal Server Error: /managers/settings/
Traceback (most recent call last):
  File "C:\Users\ADMIN\Muranga_transport\venv\Lib\site-packages\django\template\backends\django.py", line 107, in render
    return self.template.render(context)
           ^^^^^^^^^^^^^^^^^^^^^^^^^^^^^
  File "C:\Users\ADMIN\Muranga_transport\venv\Lib\site-packages\django\template\base.py", line 171, in render
    return self._render(context)
           ^^^^^^^^^^^^^^^^^^^^^
  File "C:\Users\ADMIN\Muranga_transport\venv\Lib\site-packages\django\template\base.py", line 163, in _render
    return self.nodelist.render(context)
           ^^^^^^^^^^^^^^^^^^^^^^^^^^^^^
  File "C:\Users\ADMIN\Muranga_transport\venv\Lib\site-packages\django\template\base.py", line 1016, in render
    return SafeString("".join([node.render_annotated(context) for node in self]))
                               ^^^^^^^^^^^^^^^^^^^^^^^^^^^^^^
  File "C:\Users\ADMIN\Muranga_transport\venv\Lib\site-packages\django\template\base.py", line 977, in render_annotated
    return self.render(context)
           ^^^^^^^^^^^^^^^^^^^^
  File "C:\Users\ADMIN\Muranga_transport\venv\Lib\site-packages\django\template\loader_tags.py", line 159, in render
    return compiled_parent._render(context)
           ^^^^^^^^^^^^^^^^^^^^^^^^^^^^^^^^
  File "C:\Users\ADMIN\Muranga_transport\venv\Lib\site-packages\django\template\base.py", line 163, in _render
    return self.nodelist.render(context)
           ^^^^^^^^^^^^^^^^^^^^^^^^^^^^^
  File "C:\Users\ADMIN\Muranga_transport\venv\Lib\site-packages\django\template\base.py", line 1016, in render
    return SafeString("".join([node.render_annotated(context) for node in self]))
                               ^^^^^^^^^^^^^^^^^^^^^^^^^^^^^^
  File "C:\Users\ADMIN\Muranga_transport\venv\Lib\site-packages\django\template\base.py", line 977, in render_annotated
    return self.render(context)
           ^^^^^^^^^^^^^^^^^^^^
  File "C:\Users\ADMIN\Muranga_transport\venv\Lib\site-packages\django\template\loader_tags.py", line 65, in render
    result = block.nodelist.render(context)
             ^^^^^^^^^^^^^^^^^^^^^^^^^^^^^^
  File "C:\Users\ADMIN\Muranga_transport\venv\Lib\site-packages\django\template\base.py", line 1016, in render
    return SafeString("".join([node.render_annotated(context) for node in self]))
                               ^^^^^^^^^^^^^^^^^^^^^^^^^^^^^^
  File "C:\Users\ADMIN\Muranga_transport\venv\Lib\site-packages\django\template\base.py", line 977, in render_annotated
    return self.render(context)
           ^^^^^^^^^^^^^^^^^^^^
  File "C:\Users\ADMIN\Muranga_transport\venv\Lib\site-packages\django\template\base.py", line 1075, in render
    output = self.filter_expression.resolve(context)
             ^^^^^^^^^^^^^^^^^^^^^^^^^^^^^^^^^^^^^^^
  File "C:\Users\ADMIN\Muranga_transport\venv\Lib\site-packages\django\template\base.py", line 749, in resolve
    new_obj = func(obj, *arg_vals)
              ^^^^^^^^^^^^^^^^^^^^
  File "C:\Users\ADMIN\Muranga_transport\venv\Lib\site-packages\crispy_forms\templatetags\crispy_forms_filters.py", line 58, in as_crispy_form
    template = uni_form_template(template_pack)
               ^^^^^^^^^^^^^^^^^^^^^^^^^^^^^^^^
  File "C:\Users\ADMIN\Muranga_transport\venv\Lib\site-packages\crispy_forms\templatetags\crispy_forms_filters.py", line 21, in uni_form_template
    return get_template("%s/uni_form.html" % template_pack)
           ^^^^^^^^^^^^^^^^^^^^^^^^^^^^^^^^^^^^^^^^^^^^^^^^
  File "C:\Users\ADMIN\Muranga_transport\venv\Lib\site-packages\django\template\loader.py", line 19, in get_template
    raise TemplateDoesNotExist(template_name, chain=chain)
django.template.exceptions.TemplateDoesNotExist: bootstrap5/uni_form.html

The above exception was the direct cause of the following exception:

Traceback (most recent call last):
  File "C:\Users\ADMIN\Muranga_transport\venv\Lib\site-packages\django\core\handlers\exception.py", line 55, in inner
    response = get_response(request)
               ^^^^^^^^^^^^^^^^^^^^^
  File "C:\Users\ADMIN\Muranga_transport\venv\Lib\site-packages\django\core\handlers\base.py", line 197, in _get_response
    response = wrapped_callback(request, *callback_args, **callback_kwargs)
               ^^^^^^^^^^^^^^^^^^^^^^^^^^^^^^^^^^^^^^^^^^^^^^^^^^^^^^^^^^^^
  File "C:\Users\ADMIN\Muranga_transport\venv\Lib\site-packages\django\contrib\auth\decorators.py", line 59, in _view_wrapper
    return view_func(request, *args, **kwargs)
           ^^^^^^^^^^^^^^^^^^^^^^^^^^^^^^^^^^^
  File "C:\Users\ADMIN\Muranga_transport\managers\views.py", line 995, in settings
    return render(request, 'managers/settings.html', {
           ^^^^^^^^^^^^^^^^^^^^^^^^^^^^^^^^^^^^^^^^^^^
  File "C:\Users\ADMIN\Muranga_transport\venv\Lib\site-packages\django\shortcuts.py", line 25, in render
    content = loader.render_to_string(template_name, context, request, using=using)
              ^^^^^^^^^^^^^^^^^^^^^^^^^^^^^^^^^^^^^^^^^^^^^^^^^^^^^^^^^^^^^^^^^^^^^
  File "C:\Users\ADMIN\Muranga_transport\venv\Lib\site-packages\django\template\loader.py", line 62, in render_to_string
    return template.render(context, request)
           ^^^^^^^^^^^^^^^^^^^^^^^^^^^^^^^^^
  File "C:\Users\ADMIN\Muranga_transport\venv\Lib\site-packages\django\template\backends\django.py", line 109, in render
    reraise(exc, self.backend)
  File "C:\Users\ADMIN\Muranga_transport\venv\Lib\site-packages\django\template\backends\django.py", line 130, in reraise
    raise new from exc
django.template.exceptions.TemplateDoesNotExist: bootstrap5/uni_form.html
"GET /managers/settings/ HTTP/1.1" 500 189857
Not Found: /favicon.ico
"GET /favicon.ico HTTP/1.1" 404 5679
Not Found: /favicon.ico
"GET /favicon.ico HTTP/1.1" 404 5679
"GET /static/managers/images/driver-avatar.jpg HTTP/1.1" 404 1913
Not Found: /favicon.ico
"GET /favicon.ico HTTP/1.1" 404 5679
Not Found: /favicon.ico
"GET /favicon.ico HTTP/1.1" 404 5679
Not Found: /favicon.ico
"GET /favicon.ico HTTP/1.1" 404 5679
Not Found: /favicon.ico
"GET /favicon.ico HTTP/1.1" 404 5679
Not Found: /favicon.ico
"GET /favicon.ico HTTP/1.1" 404 5679
Not Found: /favicon.ico
"GET /favicon.ico HTTP/1.1" 404 5679
Not Found: /favicon.ico
"GET /favicon.ico HTTP/1.1" 404 5679
Not Found: /favicon.ico
"GET /favicon.ico HTTP/1.1" 404 5679
Not Found: /favicon.ico
"GET /favicon.ico HTTP/1.1" 404 5679
Not Found: /favicon.ico
"GET /favicon.ico HTTP/1.1" 404 5679
Not Found: /favicon.ico
"GET /favicon.ico HTTP/1.1" 404 5679
Not Found: /favicon.ico
"GET /favicon.ico HTTP/1.1" 404 5679
Not Found: /favicon.ico
"GET /favicon.ico HTTP/1.1" 404 5679
Not Found: /favicon.ico
"GET /favicon.ico HTTP/1.1" 404 5679
Not Found: /favicon.ico
"GET /favicon.ico HTTP/1.1" 404 5679
Not Found: /favicon.ico
"GET /favicon.ico HTTP/1.1" 404 5679
Not Found: /favicon.ico
"GET /favicon.ico HTTP/1.1" 404 5679
Not Found: /favicon.ico
"GET /favicon.ico HTTP/1.1" 404 5679
Not Found: /favicon.ico
"GET /favicon.ico HTTP/1.1" 404 5679
Not Found: /favicon.ico
"GET /favicon.ico HTTP/1.1" 404 5679
Internal Server Error: /managers/maintenance/
Traceback (most recent call last):
  File "C:\Users\ADMIN\Muranga_transport\venv\Lib\site-packages\django\core\handlers\exception.py", line 55, in inner
    response = get_response(request)
               ^^^^^^^^^^^^^^^^^^^^^
  File "C:\Users\ADMIN\Muranga_transport\venv\Lib\site-packages\django\core\handlers\base.py", line 197, in _get_response
    response = wrapped_callback(request, *callback_args, **callback_kwargs)
               ^^^^^^^^^^^^^^^^^^^^^^^^^^^^^^^^^^^^^^^^^^^^^^^^^^^^^^^^^^^^
  File "C:\Users\ADMIN\Muranga_transport\venv\Lib\site-packages\django\contrib\auth\decorators.py", line 59, in _view_wrapper
    return view_func(request, *args, **kwargs)
           ^^^^^^^^^^^^^^^^^^^^^^^^^^^^^^^^^^^
  File "C:\Users\ADMIN\Muranga_transport\managers\views.py", line 69, in maintenance
    qs = MaintenanceRequest.objects.all().select_related('driver__user', 'vehicle').prefetch_related('issues').order_by('-created_at')
         ^^^^^^^^^^^^^^^^^^^^^^^^^^^^^^^^^^^^^^^^^^^^^^^^^^^^^^^^^^^^^^^^^^^^^^^^^^^^^^^^^^^^^^^^^^^^^^^^^^^^^^^^^^^^^^^^^^^^^^^^^^^^^
  File "C:\Users\ADMIN\Muranga_transport\venv\Lib\site-packages\django\db\models\query.py", line 1722, in order_by
    obj.query.add_ordering(*field_names)
  File "C:\Users\ADMIN\Muranga_transport\venv\Lib\site-packages\django\db\models\sql\query.py", line 2291, in add_ordering
    self.names_to_path(item.split(LOOKUP_SEP), self.model._meta)
  File "C:\Users\ADMIN\Muranga_transport\venv\Lib\site-packages\django\db\models\sql\query.py", line 1805, in names_to_path
    raise FieldError(
django.core.exceptions.FieldError: Cannot resolve keyword 'created_at' into field. Choices are: approved_at, approved_by, approved_by_id, assigned_task, driver, driver_id, estimated_completion, id, issues, last_update, mechanic, mechanic_id, mileage, status, submitted_at, vehicle, vehicle_id
"GET /managers/maintenance/?status=pending&priority=medium HTTP/1.1" 500 92269
Not Found: /favicon.ico
"GET /favicon.ico HTTP/1.1" 404 5679
Forbidden (CSRF token from POST incorrect.): /drivers/maintenance/new/
"POST /drivers/maintenance/new/ HTTP/1.1" 403 2503
No DriverProfile for user manager1 (ID: 3, is_staff: False, is_superuser: False)
Internal Server Error: /managers/maintenance/10/assign-mechanic/
Traceback (most recent call last):
  File "C:\Users\ADMIN\Muranga_transport\venv\Lib\site-packages\django\core\handlers\exception.py", line 55, in inner
    response = get_response(request)
               ^^^^^^^^^^^^^^^^^^^^^
  File "C:\Users\ADMIN\Muranga_transport\venv\Lib\site-packages\django\core\handlers\base.py", line 197, in _get_response
    response = wrapped_callback(request, *callback_args, **callback_kwargs)
               ^^^^^^^^^^^^^^^^^^^^^^^^^^^^^^^^^^^^^^^^^^^^^^^^^^^^^^^^^^^^
  File "C:\Users\ADMIN\Muranga_transport\venv\Lib\site-packages\django\contrib\auth\decorators.py", line 59, in _view_wrapper
    return view_func(request, *args, **kwargs)
           ^^^^^^^^^^^^^^^^^^^^^^^^^^^^^^^^^^^
  File "C:\Users\ADMIN\Muranga_transport\managers\views.py", line 227, in assign_mechanic
    MechanicTask.objects.create(
  File "C:\Users\ADMIN\Muranga_transport\venv\Lib\site-packages\django\db\models\manager.py", line 87, in manager_method
    return getattr(self.get_queryset(), name)(*args, **kwargs)
           ^^^^^^^^^^^^^^^^^^^^^^^^^^^^^^^^^^^^^^^^^^^^^^^^^^^
  File "C:\Users\ADMIN\Muranga_transport\venv\Lib\site-packages\django\db\models\query.py", line 661, in create
    obj = self.model(**kwargs)
          ^^^^^^^^^^^^^^^^^^^^
  File "C:\Users\ADMIN\Muranga_transport\venv\Lib\site-packages\django\db\models\base.py", line 569, in __init__
    raise TypeError(
TypeError: MechanicTask() got unexpected keyword arguments: 'maintenance_request', 'priority', 'notes', 'unique_task_id'
"POST /managers/maintenance/10/assign-mechanic/ HTTP/1.1" 500 92392
Internal Server Error: /managers/maintenance/10/assign-mechanic/
Traceback (most recent call last):
  File "C:\Users\ADMIN\Muranga_transport\venv\Lib\site-packages\django\core\handlers\exception.py", line 55, in inner
    response = get_response(request)
               ^^^^^^^^^^^^^^^^^^^^^
  File "C:\Users\ADMIN\Muranga_transport\venv\Lib\site-packages\django\core\handlers\base.py", line 197, in _get_response
    response = wrapped_callback(request, *callback_args, **callback_kwargs)
               ^^^^^^^^^^^^^^^^^^^^^^^^^^^^^^^^^^^^^^^^^^^^^^^^^^^^^^^^^^^^
  File "C:\Users\ADMIN\Muranga_transport\venv\Lib\site-packages\django\contrib\auth\decorators.py", line 59, in _view_wrapper
    return view_func(request, *args, **kwargs)
           ^^^^^^^^^^^^^^^^^^^^^^^^^^^^^^^^^^^
  File "C:\Users\ADMIN\Muranga_transport\managers\views.py", line 231, in assign_mechanic
    MechanicTask.objects.create(
  File "C:\Users\ADMIN\Muranga_transport\venv\Lib\site-packages\django\db\models\manager.py", line 87, in manager_method
    return getattr(self.get_queryset(), name)(*args, **kwargs)
           ^^^^^^^^^^^^^^^^^^^^^^^^^^^^^^^^^^^^^^^^^^^^^^^^^^^
  File "C:\Users\ADMIN\Muranga_transport\venv\Lib\site-packages\django\db\models\query.py", line 661, in create
    obj = self.model(**kwargs)
          ^^^^^^^^^^^^^^^^^^^^
  File "C:\Users\ADMIN\Muranga_transport\venv\Lib\site-packages\django\db\models\base.py", line 569, in __init__
    raise TypeError(
TypeError: MechanicTask() got unexpected keyword arguments: 'maintenance_request', 'priority', 'notes', 'unique_task_id'
"POST /managers/maintenance/10/assign-mechanic/ HTTP/1.1" 500 92392
Not Found: /favicon.ico
"GET /favicon.ico HTTP/1.1" 404 5679
Internal Server Error: /managers/maintenance/10/assign-mechanic/
Traceback (most recent call last):
  File "C:\Users\ADMIN\Muranga_transport\venv\Lib\site-packages\django\core\handlers\exception.py", line 55, in inner
    response = get_response(request)
               ^^^^^^^^^^^^^^^^^^^^^
  File "C:\Users\ADMIN\Muranga_transport\venv\Lib\site-packages\django\core\handlers\base.py", line 197, in _get_response
    response = wrapped_callback(request, *callback_args, **callback_kwargs)
               ^^^^^^^^^^^^^^^^^^^^^^^^^^^^^^^^^^^^^^^^^^^^^^^^^^^^^^^^^^^^
  File "C:\Users\ADMIN\Muranga_transport\venv\Lib\site-packages\django\contrib\auth\decorators.py", line 59, in _view_wrapper
    return view_func(request, *args, **kwargs)
           ^^^^^^^^^^^^^^^^^^^^^^^^^^^^^^^^^^^
  File "C:\Users\ADMIN\Muranga_transport\managers\views.py", line 227, in assign_mechanic
    MechanicTask.objects.create(
  File "C:\Users\ADMIN\Muranga_transport\venv\Lib\site-packages\django\db\models\manager.py", line 87, in manager_method
    return getattr(self.get_queryset(), name)(*args, **kwargs)
           ^^^^^^^^^^^^^^^^^^^^^^^^^^^^^^^^^^^^^^^^^^^^^^^^^^^
  File "C:\Users\ADMIN\Muranga_transport\venv\Lib\site-packages\django\db\models\query.py", line 661, in create
    obj = self.model(**kwargs)
          ^^^^^^^^^^^^^^^^^^^^
  File "C:\Users\ADMIN\Muranga_transport\venv\Lib\site-packages\django\db\models\base.py", line 569, in __init__
    raise TypeError(
TypeError: MechanicTask() got unexpected keyword arguments: 'maintenance_request', 'priority', 'notes'
"POST /managers/maintenance/10/assign-mechanic/ HTTP/1.1" 500 92037
Internal Server Error: /managers/maintenance/10/assign-mechanic/
Traceback (most recent call last):
  File "C:\Users\ADMIN\Muranga_transport\venv\Lib\site-packages\django\db\models\fields\__init__.py", line 2128, in get_prep_value
    return int(value)
           ^^^^^^^^^^
TypeError: int() argument must be a string, a bytes-like object or a real number, not 'MaintenanceRequest'

The above exception was the direct cause of the following exception:

Traceback (most recent call last):
  File "C:\Users\ADMIN\Muranga_transport\venv\Lib\site-packages\django\core\handlers\exception.py", line 55, in inner
    response = get_response(request)
               ^^^^^^^^^^^^^^^^^^^^^
  File "C:\Users\ADMIN\Muranga_transport\venv\Lib\site-packages\django\core\handlers\base.py", line 197, in _get_response
    response = wrapped_callback(request, *callback_args, **callback_kwargs)
               ^^^^^^^^^^^^^^^^^^^^^^^^^^^^^^^^^^^^^^^^^^^^^^^^^^^^^^^^^^^^
  File "C:\Users\ADMIN\Muranga_transport\venv\Lib\site-packages\django\contrib\auth\decorators.py", line 59, in _view_wrapper
    return view_func(request, *args, **kwargs)
           ^^^^^^^^^^^^^^^^^^^^^^^^^^^^^^^^^^^
  File "C:\Users\ADMIN\Muranga_transport\managers\views.py", line 227, in assign_mechanic
    MechanicTask.objects.create(
  File "C:\Users\ADMIN\Muranga_transport\venv\Lib\site-packages\django\db\models\manager.py", line 87, in manager_method
    return getattr(self.get_queryset(), name)(*args, **kwargs)
           ^^^^^^^^^^^^^^^^^^^^^^^^^^^^^^^^^^^^^^^^^^^^^^^^^^^
  File "C:\Users\ADMIN\Muranga_transport\venv\Lib\site-packages\django\db\models\query.py", line 663, in create
    obj.save(force_insert=True, using=self.db)
  File "C:\Users\ADMIN\Muranga_transport\mechanics\models.py", line 81, in save
    super().save(*args, **kwargs)
  File "C:\Users\ADMIN\Muranga_transport\venv\Lib\site-packages\django\db\models\base.py", line 902, in save
    self.save_base(
  File "C:\Users\ADMIN\Muranga_transport\venv\Lib\site-packages\django\db\models\base.py", line 1008, in save_base
    updated = self._save_table(
              ^^^^^^^^^^^^^^^^^
  File "C:\Users\ADMIN\Muranga_transport\venv\Lib\site-packages\django\db\models\base.py", line 1169, in _save_table
    results = self._do_insert(
              ^^^^^^^^^^^^^^^^
  File "C:\Users\ADMIN\Muranga_transport\venv\Lib\site-packages\django\db\models\base.py", line 1210, in _do_insert
    return manager._insert(
           ^^^^^^^^^^^^^^^^
  File "C:\Users\ADMIN\Muranga_transport\venv\Lib\site-packages\django\db\models\manager.py", line 87, in manager_method
    return getattr(self.get_queryset(), name)(*args, **kwargs)
           ^^^^^^^^^^^^^^^^^^^^^^^^^^^^^^^^^^^^^^^^^^^^^^^^^^^
  File "C:\Users\ADMIN\Muranga_transport\venv\Lib\site-packages\django\db\models\query.py", line 1868, in _insert
    return query.get_compiler(using=using).execute_sql(returning_fields)
           ^^^^^^^^^^^^^^^^^^^^^^^^^^^^^^^^^^^^^^^^^^^^^^^^^^^^^^^^^^^^^
  File "C:\Users\ADMIN\Muranga_transport\venv\Lib\site-packages\django\db\models\sql\compiler.py", line 1881, in execute_sql
    for sql, params in self.as_sql():
                       ^^^^^^^^^^^^^
  File "C:\Users\ADMIN\Muranga_transport\venv\Lib\site-packages\django\db\models\sql\compiler.py", line 1806, in as_sql
    self.prepare_value(field, self.pre_save_val(field, obj))
  File "C:\Users\ADMIN\Muranga_transport\venv\Lib\site-packages\django\db\models\sql\compiler.py", line 1741, in prepare_value
    return field.get_db_prep_save(value, connection=self.connection)
           ^^^^^^^^^^^^^^^^^^^^^^^^^^^^^^^^^^^^^^^^^^^^^^^^^^^^^^^^^
  File "C:\Users\ADMIN\Muranga_transport\venv\Lib\site-packages\django\db\models\fields\related.py", line 1189, in get_db_prep_save
    return self.target_field.get_db_prep_save(value, connection=connection)
           ^^^^^^^^^^^^^^^^^^^^^^^^^^^^^^^^^^^^^^^^^^^^^^^^^^^^^^^^^^^^^^^^
  File "C:\Users\ADMIN\Muranga_transport\venv\Lib\site-packages\django\db\models\fields\__init__.py", line 1012, in get_db_prep_save
    return self.get_db_prep_value(value, connection=connection, prepared=False)
           ^^^^^^^^^^^^^^^^^^^^^^^^^^^^^^^^^^^^^^^^^^^^^^^^^^^^^^^^^^^^^^^^^^^^
  File "C:\Users\ADMIN\Muranga_transport\venv\Lib\site-packages\django\db\models\fields\__init__.py", line 2820, in get_db_prep_value
    value = self.get_prep_value(value)
            ^^^^^^^^^^^^^^^^^^^^^^^^^^
  File "C:\Users\ADMIN\Muranga_transport\venv\Lib\site-packages\django\db\models\fields\__init__.py", line 2130, in get_prep_value
    raise e.__class__(
TypeError: Field 'id' expected a number but got <MaintenanceRequest: Request #10 - 217890 - approved>.
"POST /managers/maintenance/10/assign-mechanic/ HTTP/1.1" 500 163815
Not Found: /favicon.ico
"GET /favicon.ico HTTP/1.1" 404 5679
Internal Server Error: /managers/reports/
Traceback (most recent call last):
  File "C:\Users\ADMIN\Muranga_transport\venv\Lib\site-packages\django\core\handlers\exception.py", line 55, in inner
    response = get_response(request)
               ^^^^^^^^^^^^^^^^^^^^^
  File "C:\Users\ADMIN\Muranga_transport\venv\Lib\site-packages\django\core\handlers\base.py", line 197, in _get_response
    response = wrapped_callback(request, *callback_args, **callback_kwargs)
               ^^^^^^^^^^^^^^^^^^^^^^^^^^^^^^^^^^^^^^^^^^^^^^^^^^^^^^^^^^^^
  File "C:\Users\ADMIN\Muranga_transport\venv\Lib\site-packages\django\contrib\auth\decorators.py", line 59, in _view_wrapper
    return view_func(request, *args, **kwargs)
           ^^^^^^^^^^^^^^^^^^^^^^^^^^^^^^^^^^^
  File "C:\Users\ADMIN\Muranga_transport\managers\views.py", line 891, in reports
    requests = MaintenanceRequest.objects.select_related('driver__user', 'vehicle', 'mechanic').prefetch_related('issues').order_by('-created_at')
               ^^^^^^^^^^^^^^^^^^^^^^^^^^^^^^^^^^^^^^^^^^^^^^^^^^^^^^^^^^^^^^^^^^^^^^^^^^^^^^^^^^^^^^^^^^^^^^^^^^^^^^^^^^^^^^^^^^^^^^^^^^^^^^^^^^^
  File "C:\Users\ADMIN\Muranga_transport\venv\Lib\site-packages\django\db\models\query.py", line 1722, in order_by
    obj.query.add_ordering(*field_names)
  File "C:\Users\ADMIN\Muranga_transport\venv\Lib\site-packages\django\db\models\sql\query.py", line 2291, in add_ordering
    self.names_to_path(item.split(LOOKUP_SEP), self.model._meta)
  File "C:\Users\ADMIN\Muranga_transport\venv\Lib\site-packages\django\db\models\sql\query.py", line 1805, in names_to_path
    raise FieldError(
django.core.exceptions.FieldError: Cannot resolve keyword 'created_at' into field. Choices are: approved_at, approved_by, approved_by_id, driver, driver_id, estimated_completion, id, issues, last_update, mechanic, mechanic_id, mechanictask, mileage, status, submitted_at, vehicle, vehicle_id
"GET /managers/reports/ HTTP/1.1" 500 91887
Internal Server Error: /managers/reports/
Traceback (most recent call last):
  File "C:\Users\ADMIN\Muranga_transport\venv\Lib\site-packages\django\core\handlers\exception.py", line 55, in inner
    response = get_response(request)
               ^^^^^^^^^^^^^^^^^^^^^
  File "C:\Users\ADMIN\Muranga_transport\venv\Lib\site-packages\django\core\handlers\base.py", line 197, in _get_response
    response = wrapped_callback(request, *callback_args, **callback_kwargs)
               ^^^^^^^^^^^^^^^^^^^^^^^^^^^^^^^^^^^^^^^^^^^^^^^^^^^^^^^^^^^^
  File "C:\Users\ADMIN\Muranga_transport\venv\Lib\site-packages\django\contrib\auth\decorators.py", line 59, in _view_wrapper
    return view_func(request, *args, **kwargs)
           ^^^^^^^^^^^^^^^^^^^^^^^^^^^^^^^^^^^
  File "C:\Users\ADMIN\Muranga_transport\managers\views.py", line 891, in reports
    requests = MaintenanceRequest.objects.select_related('driver__user', 'vehicle', 'mechanic').prefetch_related('issues').order_by('-created_at')
               ^^^^^^^^^^^^^^^^^^^^^^^^^^^^^^^^^^^^^^^^^^^^^^^^^^^^^^^^^^^^^^^^^^^^^^^^^^^^^^^^^^^^^^^^^^^^^^^^^^^^^^^^^^^^^^^^^^^^^^^^^^^^^^^^^^^
  File "C:\Users\ADMIN\Muranga_transport\venv\Lib\site-packages\django\db\models\query.py", line 1722, in order_by
    obj.query.add_ordering(*field_names)
  File "C:\Users\ADMIN\Muranga_transport\venv\Lib\site-packages\django\db\models\sql\query.py", line 2291, in add_ordering
    self.names_to_path(item.split(LOOKUP_SEP), self.model._meta)
  File "C:\Users\ADMIN\Muranga_transport\venv\Lib\site-packages\django\db\models\sql\query.py", line 1805, in names_to_path
    raise FieldError(
django.core.exceptions.FieldError: Cannot resolve keyword 'created_at' into field. Choices are: approved_at, approved_by, approved_by_id, driver, driver_id, estimated_completion, id, issues, last_update, mechanic, mechanic_id, mechanictask, mileage, status, submitted_at, vehicle, vehicle_id
"GET /managers/reports/ HTTP/1.1" 500 91959
No DriverProfile for user manager1 (ID: 3, is_staff: False, is_superuser: False)
Internal Server Error: /managers/reports/
Traceback (most recent call last):
  File "C:\Users\ADMIN\Muranga_transport\venv\Lib\site-packages\django\core\handlers\exception.py", line 55, in inner
    response = get_response(request)
               ^^^^^^^^^^^^^^^^^^^^^
  File "C:\Users\ADMIN\Muranga_transport\venv\Lib\site-packages\django\core\handlers\base.py", line 197, in _get_response
    response = wrapped_callback(request, *callback_args, **callback_kwargs)
               ^^^^^^^^^^^^^^^^^^^^^^^^^^^^^^^^^^^^^^^^^^^^^^^^^^^^^^^^^^^^
  File "C:\Users\ADMIN\Muranga_transport\venv\Lib\site-packages\django\contrib\auth\decorators.py", line 59, in _view_wrapper
    return view_func(request, *args, **kwargs)
           ^^^^^^^^^^^^^^^^^^^^^^^^^^^^^^^^^^^
  File "C:\Users\ADMIN\Muranga_transport\managers\views.py", line 916, in reports
    ).annotate(
      ^^^^^^^^^
  File "C:\Users\ADMIN\Muranga_transport\venv\Lib\site-packages\django\db\models\query.py", line 1649, in annotate
    return self._annotate(args, kwargs, select=True)
           ^^^^^^^^^^^^^^^^^^^^^^^^^^^^^^^^^^^^^^^^^
  File "C:\Users\ADMIN\Muranga_transport\venv\Lib\site-packages\django\db\models\query.py", line 1701, in _annotate
    clone.query.add_annotation(
  File "C:\Users\ADMIN\Muranga_transport\venv\Lib\site-packages\django\db\models\sql\query.py", line 1218, in add_annotation
    annotation = annotation.resolve_expression(self, allow_joins=True, reuse=None)
                 ^^^^^^^^^^^^^^^^^^^^^^^^^^^^^^^^^^^^^^^^^^^^^^^^^^^^^^^^^^^^^^^^^
  File "C:\Users\ADMIN\Muranga_transport\venv\Lib\site-packages\django\db\models\aggregates.py", line 176, in resolve_expression
    result = super().resolve_expression(*args, **kwargs)
             ^^^^^^^^^^^^^^^^^^^^^^^^^^^^^^^^^^^^^^^^^^^
  File "C:\Users\ADMIN\Muranga_transport\venv\Lib\site-packages\django\db\models\aggregates.py", line 63, in resolve_expression
    c = super().resolve_expression(query, allow_joins, reuse, summarize)
        ^^^^^^^^^^^^^^^^^^^^^^^^^^^^^^^^^^^^^^^^^^^^^^^^^^^^^^^^^^^^^^^^
  File "C:\Users\ADMIN\Muranga_transport\venv\Lib\site-packages\django\db\models\expressions.py", line 300, in resolve_expression
    expr.resolve_expression(query, allow_joins, reuse, summarize, for_save)
  File "C:\Users\ADMIN\Muranga_transport\venv\Lib\site-packages\django\db\models\expressions.py", line 902, in resolve_expression
    return query.resolve_ref(self.name, allow_joins, reuse, summarize)
           ^^^^^^^^^^^^^^^^^^^^^^^^^^^^^^^^^^^^^^^^^^^^^^^^^^^^^^^^^^^
  File "C:\Users\ADMIN\Muranga_transport\venv\Lib\site-packages\django\db\models\sql\query.py", line 2049, in resolve_ref
    join_info = self.setup_joins(
                ^^^^^^^^^^^^^^^^^
  File "C:\Users\ADMIN\Muranga_transport\venv\Lib\site-packages\django\db\models\sql\query.py", line 1900, in setup_joins
    path, final_field, targets, rest = self.names_to_path(
                                       ^^^^^^^^^^^^^^^^^^^
  File "C:\Users\ADMIN\Muranga_transport\venv\Lib\site-packages\django\db\models\sql\query.py", line 1805, in names_to_path
    raise FieldError(
django.core.exceptions.FieldError: Cannot resolve keyword 'tasks' into field. Choices are: assigned_requests, email, experience_years, full_name, id, join_date, location, mechanic_id, mechanictask, phone, profile_image, specialization, status, support_requests, user, user_id
"GET /managers/reports/ HTTP/1.1" 500 128169
Not Found: /favicon.ico
"GET /favicon.ico HTTP/1.1" 404 5679
Internal Server Error: /managers/reports/
Traceback (most recent call last):
  File "C:\Users\ADMIN\Muranga_transport\venv\Lib\site-packages\django\core\handlers\exception.py", line 55, in inner
    response = get_response(request)
               ^^^^^^^^^^^^^^^^^^^^^
  File "C:\Users\ADMIN\Muranga_transport\venv\Lib\site-packages\django\core\handlers\base.py", line 197, in _get_response
    response = wrapped_callback(request, *callback_args, **callback_kwargs)
               ^^^^^^^^^^^^^^^^^^^^^^^^^^^^^^^^^^^^^^^^^^^^^^^^^^^^^^^^^^^^
  File "C:\Users\ADMIN\Muranga_transport\venv\Lib\site-packages\django\contrib\auth\decorators.py", line 59, in _view_wrapper
    return view_func(request, *args, **kwargs)
           ^^^^^^^^^^^^^^^^^^^^^^^^^^^^^^^^^^^
  File "C:\Users\ADMIN\Muranga_transport\managers\views.py", line 917, in reports
    ).annotate(
      ^^^^^^^^^
  File "C:\Users\ADMIN\Muranga_transport\venv\Lib\site-packages\django\db\models\query.py", line 1649, in annotate
    return self._annotate(args, kwargs, select=True)
           ^^^^^^^^^^^^^^^^^^^^^^^^^^^^^^^^^^^^^^^^^
  File "C:\Users\ADMIN\Muranga_transport\venv\Lib\site-packages\django\db\models\query.py", line 1701, in _annotate
    clone.query.add_annotation(
  File "C:\Users\ADMIN\Muranga_transport\venv\Lib\site-packages\django\db\models\sql\query.py", line 1218, in add_annotation
    annotation = annotation.resolve_expression(self, allow_joins=True, reuse=None)
                 ^^^^^^^^^^^^^^^^^^^^^^^^^^^^^^^^^^^^^^^^^^^^^^^^^^^^^^^^^^^^^^^^^
  File "C:\Users\ADMIN\Muranga_transport\venv\Lib\site-packages\django\db\models\aggregates.py", line 176, in resolve_expression
    result = super().resolve_expression(*args, **kwargs)
             ^^^^^^^^^^^^^^^^^^^^^^^^^^^^^^^^^^^^^^^^^^^
  File "C:\Users\ADMIN\Muranga_transport\venv\Lib\site-packages\django\db\models\aggregates.py", line 63, in resolve_expression
    c = super().resolve_expression(query, allow_joins, reuse, summarize)
        ^^^^^^^^^^^^^^^^^^^^^^^^^^^^^^^^^^^^^^^^^^^^^^^^^^^^^^^^^^^^^^^^
  File "C:\Users\ADMIN\Muranga_transport\venv\Lib\site-packages\django\db\models\expressions.py", line 300, in resolve_expression
    expr.resolve_expression(query, allow_joins, reuse, summarize, for_save)
  File "C:\Users\ADMIN\Muranga_transport\venv\Lib\site-packages\django\db\models\expressions.py", line 902, in resolve_expression
    return query.resolve_ref(self.name, allow_joins, reuse, summarize)
           ^^^^^^^^^^^^^^^^^^^^^^^^^^^^^^^^^^^^^^^^^^^^^^^^^^^^^^^^^^^
  File "C:\Users\ADMIN\Muranga_transport\venv\Lib\site-packages\django\db\models\sql\query.py", line 2049, in resolve_ref
    join_info = self.setup_joins(
                ^^^^^^^^^^^^^^^^^
  File "C:\Users\ADMIN\Muranga_transport\venv\Lib\site-packages\django\db\models\sql\query.py", line 1900, in setup_joins
    path, final_field, targets, rest = self.names_to_path(
                                       ^^^^^^^^^^^^^^^^^^^
  File "C:\Users\ADMIN\Muranga_transport\venv\Lib\site-packages\django\db\models\sql\query.py", line 1805, in names_to_path
    raise FieldError(
django.core.exceptions.FieldError: Cannot resolve keyword 'mechanictask_set' into field. Choices are: assigned_requests, email, experience_years, full_name, id, join_date, location, mechanic_id, mechanictask, phone, profile_image, specialization, status, support_requests, user, user_id
"GET /managers/reports/ HTTP/1.1" 500 128619
Not Found: /favicon.ico
"GET /favicon.ico HTTP/1.1" 404 5679
Not Found: /favicon.ico
"GET /favicon.ico HTTP/1.1" 404 5679
Not Found: /favicon.ico
"GET /favicon.ico HTTP/1.1" 404 5679
Not Found: /favicon.ico
"GET /favicon.ico HTTP/1.1" 404 5679
Not Found: /favicon.ico
"GET /favicon.ico HTTP/1.1" 404 5679
Not Found: /favicon.ico
"GET /favicon.ico HTTP/1.1" 404 5679
Not Found: /favicon.ico
"GET /favicon.ico HTTP/1.1" 404 5679
Not Found: /favicon.ico
"GET /favicon.ico HTTP/1.1" 404 5679
Not Found: /favicon.ico
"GET /favicon.ico HTTP/1.1" 404 5679
Not Found: /favicon.ico
"GET /favicon.ico HTTP/1.1" 404 5679
Internal Server Error: /managers/maintenance/17/assign-mechanic/
Traceback (most recent call last):
  File "C:\Users\ADMIN\Muranga_transport\venv\Lib\site-packages\django\db\models\fields\__init__.py", line 2128, in get_prep_value
    return int(value)
           ^^^^^^^^^^
TypeError: int() argument must be a string, a bytes-like object or a real number, not 'MaintenanceRequest'

The above exception was the direct cause of the following exception:

Traceback (most recent call last):
  File "C:\Users\ADMIN\Muranga_transport\venv\Lib\site-packages\django\core\handlers\exception.py", line 55, in inner
    response = get_response(request)
               ^^^^^^^^^^^^^^^^^^^^^
  File "C:\Users\ADMIN\Muranga_transport\venv\Lib\site-packages\django\core\handlers\base.py", line 197, in _get_response
    response = wrapped_callback(request, *callback_args, **callback_kwargs)
               ^^^^^^^^^^^^^^^^^^^^^^^^^^^^^^^^^^^^^^^^^^^^^^^^^^^^^^^^^^^^
  File "C:\Users\ADMIN\Muranga_transport\venv\Lib\site-packages\django\contrib\auth\decorators.py", line 59, in _view_wrapper
    return view_func(request, *args, **kwargs)
           ^^^^^^^^^^^^^^^^^^^^^^^^^^^^^^^^^^^
  File "C:\Users\ADMIN\Muranga_transport\managers\views.py", line 227, in assign_mechanic
    MechanicTask.objects.create(
  File "C:\Users\ADMIN\Muranga_transport\venv\Lib\site-packages\django\db\models\manager.py", line 87, in manager_method
    return getattr(self.get_queryset(), name)(*args, **kwargs)
           ^^^^^^^^^^^^^^^^^^^^^^^^^^^^^^^^^^^^^^^^^^^^^^^^^^^
  File "C:\Users\ADMIN\Muranga_transport\venv\Lib\site-packages\django\db\models\query.py", line 663, in create
    obj.save(force_insert=True, using=self.db)
  File "C:\Users\ADMIN\Muranga_transport\mechanics\models.py", line 81, in save
    super().save(*args, **kwargs)
  File "C:\Users\ADMIN\Muranga_transport\venv\Lib\site-packages\django\db\models\base.py", line 902, in save
    self.save_base(
  File "C:\Users\ADMIN\Muranga_transport\venv\Lib\site-packages\django\db\models\base.py", line 1008, in save_base
    updated = self._save_table(
              ^^^^^^^^^^^^^^^^^
  File "C:\Users\ADMIN\Muranga_transport\venv\Lib\site-packages\django\db\models\base.py", line 1169, in _save_table
    results = self._do_insert(
              ^^^^^^^^^^^^^^^^
  File "C:\Users\ADMIN\Muranga_transport\venv\Lib\site-packages\django\db\models\base.py", line 1210, in _do_insert
    return manager._insert(
           ^^^^^^^^^^^^^^^^
  File "C:\Users\ADMIN\Muranga_transport\venv\Lib\site-packages\django\db\models\manager.py", line 87, in manager_method
    return getattr(self.get_queryset(), name)(*args, **kwargs)
           ^^^^^^^^^^^^^^^^^^^^^^^^^^^^^^^^^^^^^^^^^^^^^^^^^^^
  File "C:\Users\ADMIN\Muranga_transport\venv\Lib\site-packages\django\db\models\query.py", line 1868, in _insert
    return query.get_compiler(using=using).execute_sql(returning_fields)
           ^^^^^^^^^^^^^^^^^^^^^^^^^^^^^^^^^^^^^^^^^^^^^^^^^^^^^^^^^^^^^
  File "C:\Users\ADMIN\Muranga_transport\venv\Lib\site-packages\django\db\models\sql\compiler.py", line 1881, in execute_sql
    for sql, params in self.as_sql():
                       ^^^^^^^^^^^^^
  File "C:\Users\ADMIN\Muranga_transport\venv\Lib\site-packages\django\db\models\sql\compiler.py", line 1806, in as_sql
    self.prepare_value(field, self.pre_save_val(field, obj))
  File "C:\Users\ADMIN\Muranga_transport\venv\Lib\site-packages\django\db\models\sql\compiler.py", line 1741, in prepare_value
    return field.get_db_prep_save(value, connection=self.connection)
           ^^^^^^^^^^^^^^^^^^^^^^^^^^^^^^^^^^^^^^^^^^^^^^^^^^^^^^^^^
  File "C:\Users\ADMIN\Muranga_transport\venv\Lib\site-packages\django\db\models\fields\related.py", line 1189, in get_db_prep_save
    return self.target_field.get_db_prep_save(value, connection=connection)
           ^^^^^^^^^^^^^^^^^^^^^^^^^^^^^^^^^^^^^^^^^^^^^^^^^^^^^^^^^^^^^^^^
  File "C:\Users\ADMIN\Muranga_transport\venv\Lib\site-packages\django\db\models\fields\__init__.py", line 1012, in get_db_prep_save
    return self.get_db_prep_value(value, connection=connection, prepared=False)
           ^^^^^^^^^^^^^^^^^^^^^^^^^^^^^^^^^^^^^^^^^^^^^^^^^^^^^^^^^^^^^^^^^^^^
  File "C:\Users\ADMIN\Muranga_transport\venv\Lib\site-packages\django\db\models\fields\__init__.py", line 2820, in get_db_prep_value
    value = self.get_prep_value(value)
            ^^^^^^^^^^^^^^^^^^^^^^^^^^
  File "C:\Users\ADMIN\Muranga_transport\venv\Lib\site-packages\django\db\models\fields\__init__.py", line 2130, in get_prep_value
    raise e.__class__(
TypeError: Field 'id' expected a number but got <MaintenanceRequest: Request #17 - 217890 - approved>.
"POST /managers/maintenance/17/assign-mechanic/ HTTP/1.1" 500 163125
Not Found: /favicon.ico
"GET /favicon.ico HTTP/1.1" 404 5679
No MechanicProfile for user driver_81addb4d (ID: 12, is_staff: False, is_superuser: False)
No MechanicProfile for user driver_81addb4d (ID: 12, is_staff: False, is_superuser: False)
No MechanicProfile for user driver_81addb4d (ID: 12, is_staff: False, is_superuser: False)
Not Found: /favicon.ico
"GET /favicon.ico HTTP/1.1" 404 5679
Not Found: /favicon.ico
"GET /favicon.ico HTTP/1.1" 404 5679
"GET /static/mechanics/js/task_detail.js HTTP/1.1" 404 1895
Internal Server Error: /mechanics/repair_invoice/
Traceback (most recent call last):
  File "C:\Users\ADMIN\Muranga_transport\venv\Lib\site-packages\django\db\backends\utils.py", line 105, in _execute
    return self.cursor.execute(sql, params)
           ^^^^^^^^^^^^^^^^^^^^^^^^^^^^^^^^
  File "C:\Users\ADMIN\Muranga_transport\venv\Lib\site-packages\django\db\backends\mysql\base.py", line 76, in execute
    return self.cursor.execute(query, args)
           ^^^^^^^^^^^^^^^^^^^^^^^^^^^^^^^^
  File "C:\Users\ADMIN\Muranga_transport\venv\Lib\site-packages\MySQLdb\cursors.py", line 179, in execute
    res = self._query(mogrified_query)
          ^^^^^^^^^^^^^^^^^^^^^^^^^^^^
  File "C:\Users\ADMIN\Muranga_transport\venv\Lib\site-packages\MySQLdb\cursors.py", line 330, in _query
    db.query(q)
  File "C:\Users\ADMIN\Muranga_transport\venv\Lib\site-packages\MySQLdb\connections.py", line 280, in query
    _mysql.connection.query(self, query)
MySQLdb.DataError: (1406, "Data too long for column 'task_unique_id' at row 1")

The above exception was the direct cause of the following exception:

Traceback (most recent call last):
  File "C:\Users\ADMIN\Muranga_transport\venv\Lib\site-packages\django\core\handlers\exception.py", line 55, in inner
    response = get_response(request)
               ^^^^^^^^^^^^^^^^^^^^^
  File "C:\Users\ADMIN\Muranga_transport\venv\Lib\site-packages\django\core\handlers\base.py", line 197, in _get_response
    response = wrapped_callback(request, *callback_args, **callback_kwargs)
               ^^^^^^^^^^^^^^^^^^^^^^^^^^^^^^^^^^^^^^^^^^^^^^^^^^^^^^^^^^^^
  File "C:\Users\ADMIN\Muranga_transport\venv\Lib\site-packages\django\contrib\auth\decorators.py", line 59, in _view_wrapper
    return view_func(request, *args, **kwargs)
           ^^^^^^^^^^^^^^^^^^^^^^^^^^^^^^^^^^^
  File "C:\Users\ADMIN\Muranga_transport\mechanics\views.py", line 175, in repair_invoice
    invoice.save()
  File "C:\Users\ADMIN\Muranga_transport\venv\Lib\site-packages\django\db\models\base.py", line 902, in save
    self.save_base(
  File "C:\Users\ADMIN\Muranga_transport\venv\Lib\site-packages\django\db\models\base.py", line 1008, in save_base
    updated = self._save_table(
              ^^^^^^^^^^^^^^^^^
  File "C:\Users\ADMIN\Muranga_transport\venv\Lib\site-packages\django\db\models\base.py", line 1169, in _save_table
    results = self._do_insert(
              ^^^^^^^^^^^^^^^^
  File "C:\Users\ADMIN\Muranga_transport\venv\Lib\site-packages\django\db\models\base.py", line 1210, in _do_insert
    return manager._insert(
           ^^^^^^^^^^^^^^^^
  File "C:\Users\ADMIN\Muranga_transport\venv\Lib\site-packages\django\db\models\manager.py", line 87, in manager_method
    return getattr(self.get_queryset(), name)(*args, **kwargs)
           ^^^^^^^^^^^^^^^^^^^^^^^^^^^^^^^^^^^^^^^^^^^^^^^^^^^
  File "C:\Users\ADMIN\Muranga_transport\venv\Lib\site-packages\django\db\models\query.py", line 1868, in _insert
    return query.get_compiler(using=using).execute_sql(returning_fields)
           ^^^^^^^^^^^^^^^^^^^^^^^^^^^^^^^^^^^^^^^^^^^^^^^^^^^^^^^^^^^^^
  File "C:\Users\ADMIN\Muranga_transport\venv\Lib\site-packages\django\db\models\sql\compiler.py", line 1882, in execute_sql
    cursor.execute(sql, params)
  File "C:\Users\ADMIN\Muranga_transport\venv\Lib\site-packages\django\db\backends\utils.py", line 122, in execute
    return super().execute(sql, params)
           ^^^^^^^^^^^^^^^^^^^^^^^^^^^^
  File "C:\Users\ADMIN\Muranga_transport\venv\Lib\site-packages\django\db\backends\utils.py", line 79, in execute
    return self._execute_with_wrappers(
           ^^^^^^^^^^^^^^^^^^^^^^^^^^^^
  File "C:\Users\ADMIN\Muranga_transport\venv\Lib\site-packages\django\db\backends\utils.py", line 92, in _execute_with_wrappers
    return executor(sql, params, many, context)
           ^^^^^^^^^^^^^^^^^^^^^^^^^^^^^^^^^^^^
  File "C:\Users\ADMIN\Muranga_transport\venv\Lib\site-packages\django\db\backends\utils.py", line 100, in _execute
    with self.db.wrap_database_errors:
         ^^^^^^^^^^^^^^^^^^^^^^^^^^^^
  File "C:\Users\ADMIN\Muranga_transport\venv\Lib\site-packages\django\db\utils.py", line 91, in __exit__
    raise dj_exc_value.with_traceback(traceback) from exc_value
  File "C:\Users\ADMIN\Muranga_transport\venv\Lib\site-packages\django\db\backends\utils.py", line 105, in _execute
    return self.cursor.execute(sql, params)
           ^^^^^^^^^^^^^^^^^^^^^^^^^^^^^^^^
  File "C:\Users\ADMIN\Muranga_transport\venv\Lib\site-packages\django\db\backends\mysql\base.py", line 76, in execute
    return self.cursor.execute(query, args)
           ^^^^^^^^^^^^^^^^^^^^^^^^^^^^^^^^
  File "C:\Users\ADMIN\Muranga_transport\venv\Lib\site-packages\MySQLdb\cursors.py", line 179, in execute
    res = self._query(mogrified_query)
          ^^^^^^^^^^^^^^^^^^^^^^^^^^^^
  File "C:\Users\ADMIN\Muranga_transport\venv\Lib\site-packages\MySQLdb\cursors.py", line 330, in _query
    db.query(q)
  File "C:\Users\ADMIN\Muranga_transport\venv\Lib\site-packages\MySQLdb\connections.py", line 280, in query
    _mysql.connection.query(self, query)
django.db.utils.DataError: (1406, "Data too long for column 'task_unique_id' at row 1")
"POST /mechanics/repair_invoice/ HTTP/1.1" 500 192567
Internal Server Error: /mechanics/repair_invoice/
Traceback (most recent call last):
  File "C:\Users\ADMIN\Muranga_transport\venv\Lib\site-packages\django\db\backends\utils.py", line 105, in _execute
    return self.cursor.execute(sql, params)
           ^^^^^^^^^^^^^^^^^^^^^^^^^^^^^^^^
  File "C:\Users\ADMIN\Muranga_transport\venv\Lib\site-packages\django\db\backends\mysql\base.py", line 76, in execute
    return self.cursor.execute(query, args)
           ^^^^^^^^^^^^^^^^^^^^^^^^^^^^^^^^
  File "C:\Users\ADMIN\Muranga_transport\venv\Lib\site-packages\MySQLdb\cursors.py", line 179, in execute
    res = self._query(mogrified_query)
          ^^^^^^^^^^^^^^^^^^^^^^^^^^^^
  File "C:\Users\ADMIN\Muranga_transport\venv\Lib\site-packages\MySQLdb\cursors.py", line 330, in _query
    db.query(q)
  File "C:\Users\ADMIN\Muranga_transport\venv\Lib\site-packages\MySQLdb\connections.py", line 280, in query
    _mysql.connection.query(self, query)
MySQLdb.DataError: (1406, "Data too long for column 'task_unique_id' at row 1")

The above exception was the direct cause of the following exception:

Traceback (most recent call last):
  File "C:\Users\ADMIN\Muranga_transport\venv\Lib\site-packages\django\core\handlers\exception.py", line 55, in inner
    response = get_response(request)
               ^^^^^^^^^^^^^^^^^^^^^
  File "C:\Users\ADMIN\Muranga_transport\venv\Lib\site-packages\django\core\handlers\base.py", line 197, in _get_response
    response = wrapped_callback(request, *callback_args, **callback_kwargs)
               ^^^^^^^^^^^^^^^^^^^^^^^^^^^^^^^^^^^^^^^^^^^^^^^^^^^^^^^^^^^^
  File "C:\Users\ADMIN\Muranga_transport\venv\Lib\site-packages\django\contrib\auth\decorators.py", line 59, in _view_wrapper
    return view_func(request, *args, **kwargs)
           ^^^^^^^^^^^^^^^^^^^^^^^^^^^^^^^^^^^
  File "C:\Users\ADMIN\Muranga_transport\mechanics\views.py", line 175, in repair_invoice
    invoice.save()
  File "C:\Users\ADMIN\Muranga_transport\venv\Lib\site-packages\django\db\models\base.py", line 902, in save
    self.save_base(
  File "C:\Users\ADMIN\Muranga_transport\venv\Lib\site-packages\django\db\models\base.py", line 1008, in save_base
    updated = self._save_table(
              ^^^^^^^^^^^^^^^^^
  File "C:\Users\ADMIN\Muranga_transport\venv\Lib\site-packages\django\db\models\base.py", line 1169, in _save_table
    results = self._do_insert(
              ^^^^^^^^^^^^^^^^
  File "C:\Users\ADMIN\Muranga_transport\venv\Lib\site-packages\django\db\models\base.py", line 1210, in _do_insert
    return manager._insert(
           ^^^^^^^^^^^^^^^^
  File "C:\Users\ADMIN\Muranga_transport\venv\Lib\site-packages\django\db\models\manager.py", line 87, in manager_method
    return getattr(self.get_queryset(), name)(*args, **kwargs)
           ^^^^^^^^^^^^^^^^^^^^^^^^^^^^^^^^^^^^^^^^^^^^^^^^^^^
  File "C:\Users\ADMIN\Muranga_transport\venv\Lib\site-packages\django\db\models\query.py", line 1868, in _insert
    return query.get_compiler(using=using).execute_sql(returning_fields)
           ^^^^^^^^^^^^^^^^^^^^^^^^^^^^^^^^^^^^^^^^^^^^^^^^^^^^^^^^^^^^^
  File "C:\Users\ADMIN\Muranga_transport\venv\Lib\site-packages\django\db\models\sql\compiler.py", line 1882, in execute_sql
    cursor.execute(sql, params)
  File "C:\Users\ADMIN\Muranga_transport\venv\Lib\site-packages\django\db\backends\utils.py", line 122, in execute
    return super().execute(sql, params)
           ^^^^^^^^^^^^^^^^^^^^^^^^^^^^
  File "C:\Users\ADMIN\Muranga_transport\venv\Lib\site-packages\django\db\backends\utils.py", line 79, in execute
    return self._execute_with_wrappers(
           ^^^^^^^^^^^^^^^^^^^^^^^^^^^^
  File "C:\Users\ADMIN\Muranga_transport\venv\Lib\site-packages\django\db\backends\utils.py", line 92, in _execute_with_wrappers
    return executor(sql, params, many, context)
           ^^^^^^^^^^^^^^^^^^^^^^^^^^^^^^^^^^^^
  File "C:\Users\ADMIN\Muranga_transport\venv\Lib\site-packages\django\db\backends\utils.py", line 100, in _execute
    with self.db.wrap_database_errors:
         ^^^^^^^^^^^^^^^^^^^^^^^^^^^^
  File "C:\Users\ADMIN\Muranga_transport\venv\Lib\site-packages\django\db\utils.py", line 91, in __exit__
    raise dj_exc_value.with_traceback(traceback) from exc_value
  File "C:\Users\ADMIN\Muranga_transport\venv\Lib\site-packages\django\db\backends\utils.py", line 105, in _execute
    return self.cursor.execute(sql, params)
           ^^^^^^^^^^^^^^^^^^^^^^^^^^^^^^^^
  File "C:\Users\ADMIN\Muranga_transport\venv\Lib\site-packages\django\db\backends\mysql\base.py", line 76, in execute
    return self.cursor.execute(query, args)
           ^^^^^^^^^^^^^^^^^^^^^^^^^^^^^^^^
  File "C:\Users\ADMIN\Muranga_transport\venv\Lib\site-packages\MySQLdb\cursors.py", line 179, in execute
    res = self._query(mogrified_query)
          ^^^^^^^^^^^^^^^^^^^^^^^^^^^^
  File "C:\Users\ADMIN\Muranga_transport\venv\Lib\site-packages\MySQLdb\cursors.py", line 330, in _query
    db.query(q)
  File "C:\Users\ADMIN\Muranga_transport\venv\Lib\site-packages\MySQLdb\connections.py", line 280, in query
    _mysql.connection.query(self, query)
django.db.utils.DataError: (1406, "Data too long for column 'task_unique_id' at row 1")
"POST /mechanics/repair_invoice/ HTTP/1.1" 500 192568
Internal Server Error: /mechanics/repair_invoice/
Traceback (most recent call last):
  File "C:\Users\ADMIN\Muranga_transport\venv\Lib\site-packages\django\db\backends\utils.py", line 105, in _execute
    return self.cursor.execute(sql, params)
           ^^^^^^^^^^^^^^^^^^^^^^^^^^^^^^^^
  File "C:\Users\ADMIN\Muranga_transport\venv\Lib\site-packages\django\db\backends\mysql\base.py", line 76, in execute
    return self.cursor.execute(query, args)
           ^^^^^^^^^^^^^^^^^^^^^^^^^^^^^^^^
  File "C:\Users\ADMIN\Muranga_transport\venv\Lib\site-packages\MySQLdb\cursors.py", line 179, in execute
    res = self._query(mogrified_query)
          ^^^^^^^^^^^^^^^^^^^^^^^^^^^^
  File "C:\Users\ADMIN\Muranga_transport\venv\Lib\site-packages\MySQLdb\cursors.py", line 330, in _query
    db.query(q)
  File "C:\Users\ADMIN\Muranga_transport\venv\Lib\site-packages\MySQLdb\connections.py", line 280, in query
    _mysql.connection.query(self, query)
MySQLdb.DataError: (1406, "Data too long for column 'task_unique_id' at row 1")

The above exception was the direct cause of the following exception:

Traceback (most recent call last):
  File "C:\Users\ADMIN\Muranga_transport\venv\Lib\site-packages\django\core\handlers\exception.py", line 55, in inner
    response = get_response(request)
               ^^^^^^^^^^^^^^^^^^^^^
  File "C:\Users\ADMIN\Muranga_transport\venv\Lib\site-packages\django\core\handlers\base.py", line 197, in _get_response
    response = wrapped_callback(request, *callback_args, **callback_kwargs)
               ^^^^^^^^^^^^^^^^^^^^^^^^^^^^^^^^^^^^^^^^^^^^^^^^^^^^^^^^^^^^
  File "C:\Users\ADMIN\Muranga_transport\venv\Lib\site-packages\django\contrib\auth\decorators.py", line 59, in _view_wrapper
    return view_func(request, *args, **kwargs)
           ^^^^^^^^^^^^^^^^^^^^^^^^^^^^^^^^^^^
  File "C:\Users\ADMIN\Muranga_transport\mechanics\views.py", line 175, in repair_invoice
    invoice.save()
  File "C:\Users\ADMIN\Muranga_transport\venv\Lib\site-packages\django\db\models\base.py", line 902, in save
    self.save_base(
  File "C:\Users\ADMIN\Muranga_transport\venv\Lib\site-packages\django\db\models\base.py", line 1008, in save_base
    updated = self._save_table(
              ^^^^^^^^^^^^^^^^^
  File "C:\Users\ADMIN\Muranga_transport\venv\Lib\site-packages\django\db\models\base.py", line 1169, in _save_table
    results = self._do_insert(
              ^^^^^^^^^^^^^^^^
  File "C:\Users\ADMIN\Muranga_transport\venv\Lib\site-packages\django\db\models\base.py", line 1210, in _do_insert
    return manager._insert(
           ^^^^^^^^^^^^^^^^
  File "C:\Users\ADMIN\Muranga_transport\venv\Lib\site-packages\django\db\models\manager.py", line 87, in manager_method
    return getattr(self.get_queryset(), name)(*args, **kwargs)
           ^^^^^^^^^^^^^^^^^^^^^^^^^^^^^^^^^^^^^^^^^^^^^^^^^^^
  File "C:\Users\ADMIN\Muranga_transport\venv\Lib\site-packages\django\db\models\query.py", line 1868, in _insert
    return query.get_compiler(using=using).execute_sql(returning_fields)
           ^^^^^^^^^^^^^^^^^^^^^^^^^^^^^^^^^^^^^^^^^^^^^^^^^^^^^^^^^^^^^
  File "C:\Users\ADMIN\Muranga_transport\venv\Lib\site-packages\django\db\models\sql\compiler.py", line 1882, in execute_sql
    cursor.execute(sql, params)
  File "C:\Users\ADMIN\Muranga_transport\venv\Lib\site-packages\django\db\backends\utils.py", line 122, in execute
    return super().execute(sql, params)
           ^^^^^^^^^^^^^^^^^^^^^^^^^^^^
  File "C:\Users\ADMIN\Muranga_transport\venv\Lib\site-packages\django\db\backends\utils.py", line 79, in execute
    return self._execute_with_wrappers(
           ^^^^^^^^^^^^^^^^^^^^^^^^^^^^
  File "C:\Users\ADMIN\Muranga_transport\venv\Lib\site-packages\django\db\backends\utils.py", line 92, in _execute_with_wrappers
    return executor(sql, params, many, context)
           ^^^^^^^^^^^^^^^^^^^^^^^^^^^^^^^^^^^^
  File "C:\Users\ADMIN\Muranga_transport\venv\Lib\site-packages\django\db\backends\utils.py", line 100, in _execute
    with self.db.wrap_database_errors:
         ^^^^^^^^^^^^^^^^^^^^^^^^^^^^
  File "C:\Users\ADMIN\Muranga_transport\venv\Lib\site-packages\django\db\utils.py", line 91, in __exit__
    raise dj_exc_value.with_traceback(traceback) from exc_value
  File "C:\Users\ADMIN\Muranga_transport\venv\Lib\site-packages\django\db\backends\utils.py", line 105, in _execute
    return self.cursor.execute(sql, params)
           ^^^^^^^^^^^^^^^^^^^^^^^^^^^^^^^^
  File "C:\Users\ADMIN\Muranga_transport\venv\Lib\site-packages\django\db\backends\mysql\base.py", line 76, in execute
    return self.cursor.execute(query, args)
           ^^^^^^^^^^^^^^^^^^^^^^^^^^^^^^^^
  File "C:\Users\ADMIN\Muranga_transport\venv\Lib\site-packages\MySQLdb\cursors.py", line 179, in execute
    res = self._query(mogrified_query)
          ^^^^^^^^^^^^^^^^^^^^^^^^^^^^
  File "C:\Users\ADMIN\Muranga_transport\venv\Lib\site-packages\MySQLdb\cursors.py", line 330, in _query
    db.query(q)
  File "C:\Users\ADMIN\Muranga_transport\venv\Lib\site-packages\MySQLdb\connections.py", line 280, in query
    _mysql.connection.query(self, query)
django.db.utils.DataError: (1406, "Data too long for column 'task_unique_id' at row 1")
"POST /mechanics/repair_invoice/ HTTP/1.1" 500 192568
Not Found: /favicon.ico
"GET /favicon.ico HTTP/1.1" 404 5679
Internal Server Error: /mechanics/repair_invoice/
Traceback (most recent call last):
  File "C:\Users\ADMIN\Muranga_transport\venv\Lib\site-packages\django\db\backends\utils.py", line 105, in _execute
    return self.cursor.execute(sql, params)
           ^^^^^^^^^^^^^^^^^^^^^^^^^^^^^^^^
  File "C:\Users\ADMIN\Muranga_transport\venv\Lib\site-packages\django\db\backends\mysql\base.py", line 76, in execute
    return self.cursor.execute(query, args)
           ^^^^^^^^^^^^^^^^^^^^^^^^^^^^^^^^
  File "C:\Users\ADMIN\Muranga_transport\venv\Lib\site-packages\MySQLdb\cursors.py", line 179, in execute
    res = self._query(mogrified_query)
          ^^^^^^^^^^^^^^^^^^^^^^^^^^^^
  File "C:\Users\ADMIN\Muranga_transport\venv\Lib\site-packages\MySQLdb\cursors.py", line 330, in _query
    db.query(q)
  File "C:\Users\ADMIN\Muranga_transport\venv\Lib\site-packages\MySQLdb\connections.py", line 280, in query
    _mysql.connection.query(self, query)
MySQLdb.DataError: (1406, "Data too long for column 'task_unique_id' at row 1")

The above exception was the direct cause of the following exception:

Traceback (most recent call last):
  File "C:\Users\ADMIN\Muranga_transport\venv\Lib\site-packages\django\core\handlers\exception.py", line 55, in inner
    response = get_response(request)
               ^^^^^^^^^^^^^^^^^^^^^
  File "C:\Users\ADMIN\Muranga_transport\venv\Lib\site-packages\django\core\handlers\base.py", line 197, in _get_response
    response = wrapped_callback(request, *callback_args, **callback_kwargs)
               ^^^^^^^^^^^^^^^^^^^^^^^^^^^^^^^^^^^^^^^^^^^^^^^^^^^^^^^^^^^^
  File "C:\Users\ADMIN\Muranga_transport\venv\Lib\site-packages\django\contrib\auth\decorators.py", line 59, in _view_wrapper
    return view_func(request, *args, **kwargs)
           ^^^^^^^^^^^^^^^^^^^^^^^^^^^^^^^^^^^
  File "C:\Users\ADMIN\Muranga_transport\mechanics\views.py", line 175, in repair_invoice
    invoice.save()
  File "C:\Users\ADMIN\Muranga_transport\venv\Lib\site-packages\django\db\models\base.py", line 902, in save
    self.save_base(
  File "C:\Users\ADMIN\Muranga_transport\venv\Lib\site-packages\django\db\models\base.py", line 1008, in save_base
    updated = self._save_table(
              ^^^^^^^^^^^^^^^^^
  File "C:\Users\ADMIN\Muranga_transport\venv\Lib\site-packages\django\db\models\base.py", line 1169, in _save_table
    results = self._do_insert(
              ^^^^^^^^^^^^^^^^
  File "C:\Users\ADMIN\Muranga_transport\venv\Lib\site-packages\django\db\models\base.py", line 1210, in _do_insert
    return manager._insert(
           ^^^^^^^^^^^^^^^^
  File "C:\Users\ADMIN\Muranga_transport\venv\Lib\site-packages\django\db\models\manager.py", line 87, in manager_method
    return getattr(self.get_queryset(), name)(*args, **kwargs)
           ^^^^^^^^^^^^^^^^^^^^^^^^^^^^^^^^^^^^^^^^^^^^^^^^^^^
  File "C:\Users\ADMIN\Muranga_transport\venv\Lib\site-packages\django\db\models\query.py", line 1868, in _insert
    return query.get_compiler(using=using).execute_sql(returning_fields)
           ^^^^^^^^^^^^^^^^^^^^^^^^^^^^^^^^^^^^^^^^^^^^^^^^^^^^^^^^^^^^^
  File "C:\Users\ADMIN\Muranga_transport\venv\Lib\site-packages\django\db\models\sql\compiler.py", line 1882, in execute_sql
    cursor.execute(sql, params)
  File "C:\Users\ADMIN\Muranga_transport\venv\Lib\site-packages\django\db\backends\utils.py", line 122, in execute
    return super().execute(sql, params)
           ^^^^^^^^^^^^^^^^^^^^^^^^^^^^
  File "C:\Users\ADMIN\Muranga_transport\venv\Lib\site-packages\django\db\backends\utils.py", line 79, in execute
    return self._execute_with_wrappers(
           ^^^^^^^^^^^^^^^^^^^^^^^^^^^^
  File "C:\Users\ADMIN\Muranga_transport\venv\Lib\site-packages\django\db\backends\utils.py", line 92, in _execute_with_wrappers
    return executor(sql, params, many, context)
           ^^^^^^^^^^^^^^^^^^^^^^^^^^^^^^^^^^^^
  File "C:\Users\ADMIN\Muranga_transport\venv\Lib\site-packages\django\db\backends\utils.py", line 100, in _execute
    with self.db.wrap_database_errors:
         ^^^^^^^^^^^^^^^^^^^^^^^^^^^^
  File "C:\Users\ADMIN\Muranga_transport\venv\Lib\site-packages\django\db\utils.py", line 91, in __exit__
    raise dj_exc_value.with_traceback(traceback) from exc_value
  File "C:\Users\ADMIN\Muranga_transport\venv\Lib\site-packages\django\db\backends\utils.py", line 105, in _execute
    return self.cursor.execute(sql, params)
           ^^^^^^^^^^^^^^^^^^^^^^^^^^^^^^^^
  File "C:\Users\ADMIN\Muranga_transport\venv\Lib\site-packages\django\db\backends\mysql\base.py", line 76, in execute
    return self.cursor.execute(query, args)
           ^^^^^^^^^^^^^^^^^^^^^^^^^^^^^^^^
  File "C:\Users\ADMIN\Muranga_transport\venv\Lib\site-packages\MySQLdb\cursors.py", line 179, in execute
    res = self._query(mogrified_query)
          ^^^^^^^^^^^^^^^^^^^^^^^^^^^^
  File "C:\Users\ADMIN\Muranga_transport\venv\Lib\site-packages\MySQLdb\cursors.py", line 330, in _query
    db.query(q)
  File "C:\Users\ADMIN\Muranga_transport\venv\Lib\site-packages\MySQLdb\connections.py", line 280, in query
    _mysql.connection.query(self, query)
django.db.utils.DataError: (1406, "Data too long for column 'task_unique_id' at row 1")
"POST /mechanics/repair_invoice/ HTTP/1.1" 500 192568
Forbidden (CSRF token from POST incorrect.): /login/
"POST /login/ HTTP/1.1" 403 2503
Not Found: /favicon.ico
"GET /favicon.ico HTTP/1.1" 404 5679
Forbidden (CSRF token from POST incorrect.): /login/
"POST /login/ HTTP/1.1" 403 2503
Not Found: /favicon.ico
"GET /favicon.ico HTTP/1.1" 404 5679
No MechanicProfile for user driver_81addb4d (ID: 12, is_staff: False, is_superuser: False)
"GET /static/mechanics/js/task_detail.js HTTP/1.1" 404 1895
"GET /static/mechanics/js/task_detail.js HTTP/1.1" 404 1895
Not Found: /favicon.ico
"GET /favicon.ico HTTP/1.1" 404 5679
Not Found: /favicon.ico
"GET /favicon.ico HTTP/1.1" 404 5679
Internal Server Error: /mechanics/tasks/
Traceback (most recent call last):
  File "C:\Users\ADMIN\Muranga_transport\venv\Lib\site-packages\django\template\base.py", line 890, in _resolve_lookup
    raise TypeError
TypeError

During handling of the above exception, another exception occurred:

Traceback (most recent call last):
  File "C:\Users\ADMIN\Muranga_transport\venv\Lib\site-packages\django\template\base.py", line 901, in _resolve_lookup
    current = getattr(current, bit)
              ^^^^^^^^^^^^^^^^^^^^^
AttributeError: 'NoneType' object has no attribute 'vehicle'

During handling of the above exception, another exception occurred:

Traceback (most recent call last):
  File "C:\Users\ADMIN\Muranga_transport\venv\Lib\site-packages\django\template\base.py", line 907, in _resolve_lookup
    current = current[int(bit)]
                      ^^^^^^^^
ValueError: invalid literal for int() with base 10: 'vehicle'

During handling of the above exception, another exception occurred:

Traceback (most recent call last):
  File "C:\Users\ADMIN\Muranga_transport\venv\Lib\site-packages\django\core\handlers\exception.py", line 55, in inner
    response = get_response(request)
               ^^^^^^^^^^^^^^^^^^^^^
  File "C:\Users\ADMIN\Muranga_transport\venv\Lib\site-packages\django\core\handlers\base.py", line 197, in _get_response
    response = wrapped_callback(request, *callback_args, **callback_kwargs)
               ^^^^^^^^^^^^^^^^^^^^^^^^^^^^^^^^^^^^^^^^^^^^^^^^^^^^^^^^^^^^
  File "C:\Users\ADMIN\Muranga_transport\venv\Lib\site-packages\django\contrib\auth\decorators.py", line 59, in _view_wrapper
    return view_func(request, *args, **kwargs)
           ^^^^^^^^^^^^^^^^^^^^^^^^^^^^^^^^^^^
  File "C:\Users\ADMIN\Muranga_transport\mechanics\views.py", line 435, in tasks
    return render(request, 'mechanics/tasks.html', {
           ^^^^^^^^^^^^^^^^^^^^^^^^^^^^^^^^^^^^^^^^^
  File "C:\Users\ADMIN\Muranga_transport\venv\Lib\site-packages\django\shortcuts.py", line 25, in render
    content = loader.render_to_string(template_name, context, request, using=using)
              ^^^^^^^^^^^^^^^^^^^^^^^^^^^^^^^^^^^^^^^^^^^^^^^^^^^^^^^^^^^^^^^^^^^^^
  File "C:\Users\ADMIN\Muranga_transport\venv\Lib\site-packages\django\template\loader.py", line 62, in render_to_string
    return template.render(context, request)
           ^^^^^^^^^^^^^^^^^^^^^^^^^^^^^^^^^
  File "C:\Users\ADMIN\Muranga_transport\venv\Lib\site-packages\django\template\backends\django.py", line 107, in render
    return self.template.render(context)
           ^^^^^^^^^^^^^^^^^^^^^^^^^^^^^
  File "C:\Users\ADMIN\Muranga_transport\venv\Lib\site-packages\django\template\base.py", line 171, in render
    return self._render(context)
           ^^^^^^^^^^^^^^^^^^^^^
  File "C:\Users\ADMIN\Muranga_transport\venv\Lib\site-packages\django\template\base.py", line 163, in _render
    return self.nodelist.render(context)
           ^^^^^^^^^^^^^^^^^^^^^^^^^^^^^
  File "C:\Users\ADMIN\Muranga_transport\venv\Lib\site-packages\django\template\base.py", line 1016, in render
    return SafeString("".join([node.render_annotated(context) for node in self]))
                               ^^^^^^^^^^^^^^^^^^^^^^^^^^^^^^
  File "C:\Users\ADMIN\Muranga_transport\venv\Lib\site-packages\django\template\base.py", line 977, in render_annotated
    return self.render(context)
           ^^^^^^^^^^^^^^^^^^^^
  File "C:\Users\ADMIN\Muranga_transport\venv\Lib\site-packages\django\template\loader_tags.py", line 159, in render
    return compiled_parent._render(context)
           ^^^^^^^^^^^^^^^^^^^^^^^^^^^^^^^^
  File "C:\Users\ADMIN\Muranga_transport\venv\Lib\site-packages\django\template\base.py", line 163, in _render
    return self.nodelist.render(context)
           ^^^^^^^^^^^^^^^^^^^^^^^^^^^^^
  File "C:\Users\ADMIN\Muranga_transport\venv\Lib\site-packages\django\template\base.py", line 1016, in render
    return SafeString("".join([node.render_annotated(context) for node in self]))
                               ^^^^^^^^^^^^^^^^^^^^^^^^^^^^^^
  File "C:\Users\ADMIN\Muranga_transport\venv\Lib\site-packages\django\template\base.py", line 977, in render_annotated
    return self.render(context)
           ^^^^^^^^^^^^^^^^^^^^
  File "C:\Users\ADMIN\Muranga_transport\venv\Lib\site-packages\django\template\loader_tags.py", line 65, in render
    result = block.nodelist.render(context)
             ^^^^^^^^^^^^^^^^^^^^^^^^^^^^^^
  File "C:\Users\ADMIN\Muranga_transport\venv\Lib\site-packages\django\template\base.py", line 1016, in render
    return SafeString("".join([node.render_annotated(context) for node in self]))
                               ^^^^^^^^^^^^^^^^^^^^^^^^^^^^^^
  File "C:\Users\ADMIN\Muranga_transport\venv\Lib\site-packages\django\template\base.py", line 977, in render_annotated
    return self.render(context)
           ^^^^^^^^^^^^^^^^^^^^
  File "C:\Users\ADMIN\Muranga_transport\venv\Lib\site-packages\django\template\defaulttags.py", line 327, in render
    return nodelist.render(context)
           ^^^^^^^^^^^^^^^^^^^^^^^^
  File "C:\Users\ADMIN\Muranga_transport\venv\Lib\site-packages\django\template\base.py", line 1016, in render
    return SafeString("".join([node.render_annotated(context) for node in self]))
                               ^^^^^^^^^^^^^^^^^^^^^^^^^^^^^^
  File "C:\Users\ADMIN\Muranga_transport\venv\Lib\site-packages\django\template\base.py", line 977, in render_annotated
    return self.render(context)
           ^^^^^^^^^^^^^^^^^^^^
  File "C:\Users\ADMIN\Muranga_transport\venv\Lib\site-packages\django\template\defaulttags.py", line 243, in render
    nodelist.append(node.render_annotated(context))
                    ^^^^^^^^^^^^^^^^^^^^^^^^^^^^^^
  File "C:\Users\ADMIN\Muranga_transport\venv\Lib\site-packages\django\template\base.py", line 977, in render_annotated
    return self.render(context)
           ^^^^^^^^^^^^^^^^^^^^
  File "C:\Users\ADMIN\Muranga_transport\venv\Lib\site-packages\django\template\base.py", line 1075, in render
    output = self.filter_expression.resolve(context)
             ^^^^^^^^^^^^^^^^^^^^^^^^^^^^^^^^^^^^^^^
  File "C:\Users\ADMIN\Muranga_transport\venv\Lib\site-packages\django\template\base.py", line 743, in resolve
    arg_vals.append(arg.resolve(context))
                    ^^^^^^^^^^^^^^^^^^^^
  File "C:\Users\ADMIN\Muranga_transport\venv\Lib\site-packages\django\template\base.py", line 854, in resolve
    value = self._resolve_lookup(context)
            ^^^^^^^^^^^^^^^^^^^^^^^^^^^^^
  File "C:\Users\ADMIN\Muranga_transport\venv\Lib\site-packages\django\template\base.py", line 914, in _resolve_lookup
    raise VariableDoesNotExist(
django.template.base.VariableDoesNotExist: Failed lookup for key [vehicle] in None
"GET /mechanics/tasks/ HTTP/1.1" 500 216689
Internal Server Error: /managers/job-management/
Traceback (most recent call last):
  File "C:\Users\ADMIN\Muranga_transport\venv\Lib\site-packages\django\core\handlers\exception.py", line 55, in inner
    response = get_response(request)
               ^^^^^^^^^^^^^^^^^^^^^
  File "C:\Users\ADMIN\Muranga_transport\venv\Lib\site-packages\django\core\handlers\base.py", line 197, in _get_response
    response = wrapped_callback(request, *callback_args, **callback_kwargs)
               ^^^^^^^^^^^^^^^^^^^^^^^^^^^^^^^^^^^^^^^^^^^^^^^^^^^^^^^^^^^^
  File "C:\Users\ADMIN\Muranga_transport\venv\Lib\site-packages\django\contrib\auth\decorators.py", line 59, in _view_wrapper
    return view_func(request, *args, **kwargs)
           ^^^^^^^^^^^^^^^^^^^^^^^^^^^^^^^^^^^
  File "C:\Users\ADMIN\Muranga_transport\managers\views.py", line 562, in job_management
    return render(request, "managers/job_management.html", {
           ^^^^^^^^^^^^^^^^^^^^^^^^^^^^^^^^^^^^^^^^^^^^^^^^^
  File "C:\Users\ADMIN\Muranga_transport\venv\Lib\site-packages\django\shortcuts.py", line 25, in render
    content = loader.render_to_string(template_name, context, request, using=using)
              ^^^^^^^^^^^^^^^^^^^^^^^^^^^^^^^^^^^^^^^^^^^^^^^^^^^^^^^^^^^^^^^^^^^^^
  File "C:\Users\ADMIN\Muranga_transport\venv\Lib\site-packages\django\template\loader.py", line 62, in render_to_string
    return template.render(context, request)
           ^^^^^^^^^^^^^^^^^^^^^^^^^^^^^^^^^
  File "C:\Users\ADMIN\Muranga_transport\venv\Lib\site-packages\django\template\backends\django.py", line 107, in render
    return self.template.render(context)
           ^^^^^^^^^^^^^^^^^^^^^^^^^^^^^
  File "C:\Users\ADMIN\Muranga_transport\venv\Lib\site-packages\django\template\base.py", line 171, in render
    return self._render(context)
           ^^^^^^^^^^^^^^^^^^^^^
  File "C:\Users\ADMIN\Muranga_transport\venv\Lib\site-packages\django\template\base.py", line 163, in _render
    return self.nodelist.render(context)
           ^^^^^^^^^^^^^^^^^^^^^^^^^^^^^
  File "C:\Users\ADMIN\Muranga_transport\venv\Lib\site-packages\django\template\base.py", line 1016, in render
    return SafeString("".join([node.render_annotated(context) for node in self]))
                               ^^^^^^^^^^^^^^^^^^^^^^^^^^^^^^
  File "C:\Users\ADMIN\Muranga_transport\venv\Lib\site-packages\django\template\base.py", line 977, in render_annotated
    return self.render(context)
           ^^^^^^^^^^^^^^^^^^^^
  File "C:\Users\ADMIN\Muranga_transport\venv\Lib\site-packages\django\template\loader_tags.py", line 159, in render
    return compiled_parent._render(context)
           ^^^^^^^^^^^^^^^^^^^^^^^^^^^^^^^^
  File "C:\Users\ADMIN\Muranga_transport\venv\Lib\site-packages\django\template\base.py", line 163, in _render
    return self.nodelist.render(context)
           ^^^^^^^^^^^^^^^^^^^^^^^^^^^^^
  File "C:\Users\ADMIN\Muranga_transport\venv\Lib\site-packages\django\template\base.py", line 1016, in render
    return SafeString("".join([node.render_annotated(context) for node in self]))
                               ^^^^^^^^^^^^^^^^^^^^^^^^^^^^^^
  File "C:\Users\ADMIN\Muranga_transport\venv\Lib\site-packages\django\template\base.py", line 977, in render_annotated
    return self.render(context)
           ^^^^^^^^^^^^^^^^^^^^
  File "C:\Users\ADMIN\Muranga_transport\venv\Lib\site-packages\django\template\defaulttags.py", line 480, in render
    url = reverse(view_name, args=args, kwargs=kwargs, current_app=current_app)
          ^^^^^^^^^^^^^^^^^^^^^^^^^^^^^^^^^^^^^^^^^^^^^^^^^^^^^^^^^^^^^^^^^^^^^
  File "C:\Users\ADMIN\Muranga_transport\venv\Lib\site-packages\django\urls\base.py", line 98, in reverse
    resolved_url = resolver._reverse_with_prefix(view, prefix, *args, **kwargs)
                   ^^^^^^^^^^^^^^^^^^^^^^^^^^^^^^^^^^^^^^^^^^^^^^^^^^^^^^^^^^^^
  File "C:\Users\ADMIN\Muranga_transport\venv\Lib\site-packages\django\urls\resolvers.py", line 831, in _reverse_with_prefix
    raise NoReverseMatch(msg)
django.urls.exceptions.NoReverseMatch: Reverse for 'mechanic_tasks' not found. 'mechanic_tasks' is not a valid view function or pattern name.
"GET /managers/job-management/ HTTP/1.1" 500 161718
Not Found: /favicon.ico
"GET /favicon.ico HTTP/1.1" 404 5679
